{"trial_id": "00", "hyperparameters": {"space": [{"class_name": "Choice", "config": {"name": "activation", "default": "LeakyReLU", "conditions": [], "values": ["LeakyReLU", "gelu"], "ordered": false}}, {"class_name": "Int", "config": {"name": "layer_1", "default": null, "conditions": [], "min_value": 0, "max_value": 512, "step": 16, "sampling": "linear"}}, {"class_name": "Int", "config": {"name": "layer_2", "default": null, "conditions": [], "min_value": 0, "max_value": 512, "step": 16, "sampling": "linear"}}, {"class_name": "Int", "config": {"name": "layer_3", "default": null, "conditions": [], "min_value": 0, "max_value": 512, "step": 16, "sampling": "linear"}}, {"class_name": "Choice", "config": {"name": "learning_rate", "default": 0.01, "conditions": [], "values": [0.01, 0.001, 0.0001], "ordered": true}}], "values": {"activation": "LeakyReLU", "layer_1": 192, "layer_2": 384, "layer_3": 160, "learning_rate": 0.001}}, "metrics": {"metrics": {}}, "score": null, "best_step": 0, "status": "FAILED", "message": "Traceback (most recent call last):\n  File \"C:\\Users\\jonat\\AppData\\Roaming\\Python\\Python310\\site-packages\\keras_tuner\\src\\engine\\base_tuner.py\", line 273, in _try_run_and_update_trial\n    try:\n  File \"C:\\Users\\jonat\\AppData\\Roaming\\Python\\Python310\\site-packages\\keras_tuner\\src\\engine\\base_tuner.py\", line 238, in _run_and_update_trial\n    def _run_and_update_trial(self, trial, *fit_args, **fit_kwargs):\n  File \"C:\\Users\\jonat\\AppData\\Roaming\\Python\\Python310\\site-packages\\keras_tuner\\src\\engine\\tuner.py\", line 314, in run_trial\n    obj_value = self._build_and_fit_model(trial, *args, **copied_kwargs)\n  File \"C:\\Users\\jonat\\AppData\\Roaming\\Python\\Python310\\site-packages\\keras_tuner\\src\\engine\\tuner.py\", line 233, in _build_and_fit_model\n    results = self.hypermodel.fit(hp, model, *args, **kwargs)\n  File \"C:\\Users\\jonat\\AppData\\Roaming\\Python\\Python310\\site-packages\\keras_tuner\\src\\engine\\hypermodel.py\", line 149, in fit\n    return model.fit(*args, **kwargs)\n  File \"C:\\Users\\jonat\\AppData\\Roaming\\Python\\Python310\\site-packages\\keras\\src\\utils\\traceback_utils.py\", line 70, in error_handler\n    raise e.with_traceback(filtered_tb) from None\n  File \"C:\\Users\\jonat\\AppData\\Roaming\\Python\\Python310\\site-packages\\tensorflow\\python\\eager\\execute.py\", line 60, in quick_execute\n    tensors = pywrap_tfe.TFE_Py_Execute(ctx._handle, device_name, op_name,\ntensorflow.python.framework.errors_impl.InvalidArgumentError: Graph execution error:\n\nDetected at node sparse_categorical_crossentropy/SparseSoftmaxCrossEntropyWithLogits/SparseSoftmaxCrossEntropyWithLogits defined at (most recent call last):\n  File \"D:\\anaconda\\lib\\runpy.py\", line 196, in _run_module_as_main\n\n  File \"D:\\anaconda\\lib\\runpy.py\", line 86, in _run_code\n\n  File \"D:\\anaconda\\lib\\site-packages\\ipykernel_launcher.py\", line 17, in <module>\n\n  File \"D:\\anaconda\\lib\\site-packages\\traitlets\\config\\application.py\", line 992, in launch_instance\n\n  File \"D:\\anaconda\\lib\\site-packages\\ipykernel\\kernelapp.py\", line 711, in start\n\n  File \"D:\\anaconda\\lib\\site-packages\\tornado\\platform\\asyncio.py\", line 199, in start\n\n  File \"D:\\anaconda\\lib\\asyncio\\base_events.py\", line 603, in run_forever\n\n  File \"D:\\anaconda\\lib\\asyncio\\base_events.py\", line 1906, in _run_once\n\n  File \"D:\\anaconda\\lib\\asyncio\\events.py\", line 80, in _run\n\n  File \"D:\\anaconda\\lib\\site-packages\\ipykernel\\kernelbase.py\", line 510, in dispatch_queue\n\n  File \"D:\\anaconda\\lib\\site-packages\\ipykernel\\kernelbase.py\", line 499, in process_one\n\n  File \"D:\\anaconda\\lib\\site-packages\\ipykernel\\kernelbase.py\", line 406, in dispatch_shell\n\n  File \"D:\\anaconda\\lib\\site-packages\\ipykernel\\kernelbase.py\", line 729, in execute_request\n\n  File \"D:\\anaconda\\lib\\site-packages\\ipykernel\\ipkernel.py\", line 411, in do_execute\n\n  File \"D:\\anaconda\\lib\\site-packages\\ipykernel\\zmqshell.py\", line 531, in run_cell\n\n  File \"D:\\anaconda\\lib\\site-packages\\IPython\\core\\interactiveshell.py\", line 2961, in run_cell\n\n  File \"D:\\anaconda\\lib\\site-packages\\IPython\\core\\interactiveshell.py\", line 3016, in _run_cell\n\n  File \"D:\\anaconda\\lib\\site-packages\\IPython\\core\\async_helpers.py\", line 129, in _pseudo_sync_runner\n\n  File \"D:\\anaconda\\lib\\site-packages\\IPython\\core\\interactiveshell.py\", line 3221, in run_cell_async\n\n  File \"D:\\anaconda\\lib\\site-packages\\IPython\\core\\interactiveshell.py\", line 3400, in run_ast_nodes\n\n  File \"D:\\anaconda\\lib\\site-packages\\IPython\\core\\interactiveshell.py\", line 3460, in run_code\n\n  File \"C:\\Users\\jonat\\AppData\\Local\\Temp\\ipykernel_9492\\1432508054.py\", line 1, in <module>\n\n  File \"C:\\Users\\jonat\\AppData\\Roaming\\Python\\Python310\\site-packages\\keras_tuner\\src\\engine\\base_tuner.py\", line 233, in search\n\n  File \"C:\\Users\\jonat\\AppData\\Roaming\\Python\\Python310\\site-packages\\keras_tuner\\src\\engine\\base_tuner.py\", line 273, in _try_run_and_update_trial\n\n  File \"C:\\Users\\jonat\\AppData\\Roaming\\Python\\Python310\\site-packages\\keras_tuner\\src\\engine\\base_tuner.py\", line 238, in _run_and_update_trial\n\n  File \"C:\\Users\\jonat\\AppData\\Roaming\\Python\\Python310\\site-packages\\keras_tuner\\src\\engine\\tuner.py\", line 314, in run_trial\n\n  File \"C:\\Users\\jonat\\AppData\\Roaming\\Python\\Python310\\site-packages\\keras_tuner\\src\\engine\\tuner.py\", line 233, in _build_and_fit_model\n\n  File \"C:\\Users\\jonat\\AppData\\Roaming\\Python\\Python310\\site-packages\\keras_tuner\\src\\engine\\hypermodel.py\", line 149, in fit\n\n  File \"C:\\Users\\jonat\\AppData\\Roaming\\Python\\Python310\\site-packages\\keras\\src\\utils\\traceback_utils.py\", line 65, in error_handler\n\n  File \"C:\\Users\\jonat\\AppData\\Roaming\\Python\\Python310\\site-packages\\keras\\src\\engine\\training.py\", line 1783, in fit\n\n  File \"C:\\Users\\jonat\\AppData\\Roaming\\Python\\Python310\\site-packages\\keras\\src\\engine\\training.py\", line 1377, in train_function\n\n  File \"C:\\Users\\jonat\\AppData\\Roaming\\Python\\Python310\\site-packages\\keras\\src\\engine\\training.py\", line 1360, in step_function\n\n  File \"C:\\Users\\jonat\\AppData\\Roaming\\Python\\Python310\\site-packages\\keras\\src\\engine\\training.py\", line 1349, in run_step\n\n  File \"C:\\Users\\jonat\\AppData\\Roaming\\Python\\Python310\\site-packages\\keras\\src\\engine\\training.py\", line 1127, in train_step\n\n  File \"C:\\Users\\jonat\\AppData\\Roaming\\Python\\Python310\\site-packages\\keras\\src\\engine\\training.py\", line 1185, in compute_loss\n\n  File \"C:\\Users\\jonat\\AppData\\Roaming\\Python\\Python310\\site-packages\\keras\\src\\engine\\compile_utils.py\", line 277, in __call__\n\n  File \"C:\\Users\\jonat\\AppData\\Roaming\\Python\\Python310\\site-packages\\keras\\src\\losses.py\", line 143, in __call__\n\n  File \"C:\\Users\\jonat\\AppData\\Roaming\\Python\\Python310\\site-packages\\keras\\src\\losses.py\", line 270, in call\n\n  File \"C:\\Users\\jonat\\AppData\\Roaming\\Python\\Python310\\site-packages\\keras\\src\\losses.py\", line 2454, in sparse_categorical_crossentropy\n\n  File \"C:\\Users\\jonat\\AppData\\Roaming\\Python\\Python310\\site-packages\\keras\\src\\backend.py\", line 5777, in sparse_categorical_crossentropy\n\nReceived a label value of 23 which is outside the valid range of [0, 6).  Label values: 20 1 20 1 0 1 23 14 10 21 9 14 5 0 15 1 17 6 18 17 6 5 0 7 21 18 20 20 6 22 5 14\n\t [[{{node sparse_categorical_crossentropy/SparseSoftmaxCrossEntropyWithLogits/SparseSoftmaxCrossEntropyWithLogits}}]] [Op:__inference_train_function_567330]\n"}